Workbook

Sheet ExponentsPractic_pst
A1: Teacher Name: | B1: R Miller
A2: Class: | B2: Mathematics 9
A3: Assignment Name: | B3: Exponents Practice Quiz (Part A/B)
A4: Due Date: | B4: 46295
A5: Points Possible: | B5: 48
A6: Extra Points: | B6: 0
A7: Score Type: | B7: POINTS
A8: Student Num | B8: Student Name | C8: Score | D8: Part A | E8: Part B | F8: Percent | H8: Part A Average | I8: Part B Average
A9: 26281 | B9: Annicchiarico, Cohen | C9: =D9+E9 -> 30 | D9: 17 | E9: 13 | F9: =C9/48 -> 0.625 | H9: =average(D9:D28)/23 -> 0.58352403 | I9: =AVERAGE(E9:E28)/25 -> 0.65578947
A10: 26285 | B10: Butcher, AJ | C10: =D10+E10 -> 28.5 | D10: 11 | E10: 17.5 | F10: =C10/48 -> 0.59375
A11: 37905 | B11: Crann, Meekyo | C11: =D11+E11 -> 12 | D11: 6 | E11: 6 | F11: =C11/48 -> 0.25
A12: 28574 | B12: Dahl, Jake | C12: =D12+E12 -> 22 | D12: 7 | E12: 15 | F12: =C12/48 -> 0.45833333
A13: 26288 | B13: Dick, Calder | C13: =D13+E13 -> 39 | D13: 18 | E13: 21 | F13: =C13/48 -> 0.8125
A14: 26289 | B14: Ewanchuk, Brayden | C14: =D14+E14 -> 32 | D14: 14 | E14: 18 | F14: =C14/48 -> 0.66666667
A15: 36672 | B15: Fulkerth, Hunter | C15: =D15+E15 -> 32.5 | D15: 17 | E15: 15.5 | F15: =C15/48 -> 0.67708333
A16: 24820 | B16: Grimsdale, Charles | C16: =D16+E16 -> 22.5 | D16: 8 | E16: 14.5 | F16: =C16/48 -> 0.46875
A17: 30685 | B17: Gudge, Hudson | C17: =IF(D17+E17=0, "", D17+E17) | F17: =C17/48 -> 0
A18: 26293 | B18: Hrynyk, Hallie | C18: =D18+E18 -> 33.5 | D18: 15 | E18: 18.5 | F18: =C18/48 -> 0.69791667
A19: 26521 | B19: Hughes, Jace | C19: 21 | D19: 11 | E19: 11 | F19: =C19/48 -> 0.4375
A20: 28059 | B20: Kimmel, Emmy | C20: =D20+E20 -> 24 | D20: 9 | E20: 15 | F20: =C20/48 -> 0.5
A21: 26657 | B21: Krueger, Colin | C21: =D21+E21 -> 24 | D21: 15 | E21: 9 | F21: =C21/48 -> 0.5
A22: 26297 | B22: Mueller, Marco | C22: =D22+E22 -> 46 | D22: 21 | E22: 25 | F22: =C22/48 -> 0.95833333
A23: 26298 | B23: Park, Edwin | C23: =D23+E23 -> 42.5 | D23: 20 | E23: 22.5 | F23: =C23/48 -> 0.88541667
A24: 26300 | B24: Ruttan, Logan | C24: =D24+E24 -> 41 | D24: 18 | E24: 23 | F24: =C24/48 -> 0.85416667
A25: 26301 | B25: Schimmel, Calvin | C25: =D25+E25 -> 23 | D25: 10 | E25: 13 | F25: =C25/48 -> 0.47916667
A26: 26304 | B26: Stephenson, Cale | C26: =D26+E26 -> 40.5 | D26: 16 | E26: 24.5 | F26: =C26/48 -> 0.84375
A27: 26305 | B27: Stephenson, Callum | C27: =D27+E27 -> 42 | D27: 18 | E27: 24 | F27: =C27/48 -> 0.875
A28: 38395 | B28: Tuks Gagnon, Adelyn | C28: =D28+E28 -> 9.5 | D28: 4 | E28: 5.5 | F28: =C28/48 -> 0.19791667

Sheet Item Analysis
A1: Item analysis with partial credit
A2: =ExponentsPractic_pst!B3 -> Exponents Practice Quiz (Part A/B)
A3: Enter each item’s maximum in row 13, then earned points in rows 29–78. Decimals are allowed. Blank = ungraded; 0 = no credit.
A5: Current section results | B5: Maximum | C5: Scored students | D5: Mean points | E5: Mean / maximum | F5: Item maxima | G5: Maximum check
A6: Part A | B6: 23 | C6: =COUNT(ExponentsPractic_pst!D9:D28) -> 19 | D6: =IF(C6=0,"",AVERAGE(ExponentsPractic_pst!D9:D28)) -> 13.421053 | E6: =IF(C6=0,"",D6/B6) -> 0.58352403 | F6: =SUM(C13:V13) -> 23 | G6: =IF(COUNTIF(C13:V13,">0")<20,"Set all 20 maxima",IF(F6=B6,"Matches","Review maxima")) -> Matches
A7: Part B | B7: 25 | C7: =COUNT(ExponentsPractic_pst!E9:E28) -> 19 | D7: =IF(C7=0,"",AVERAGE(ExponentsPractic_pst!E9:E28)) -> 16.394737 | E7: =IF(C7=0,"",D7/B7) -> 0.65578947 | F7: =SUM(W13:AL13) -> 25 | G7: =IF(COUNTIF(W13:AL13,">0")<16,"Set all 16 maxima",IF(F7=B7,"Matches","Review maxima")) -> Matches
A8: Section scores above are linked. Enter question scores below; the source does not contain question-level scores.
A9: Configured items | B9: =COUNTIF(C13:AL13,">0") -> 36 | C9: Total maximum | D9: =SUM(C13:AL13) -> 48 | E9: Complete students | F9: =COUNT(AM30:AM79) -> 19
A10: Question setup | B10: =IF(B9<36,"Set all 36 maxima",IF(AND(F6=B6,F7=B7),"Maxima match both parts","Review section maxima")) -> Maxima match both parts
A12: Question analysis | C12: A-MC1 | D12: A-MC2 | E12: A-MC3 | F12: A-MC4 | G12: A-MC5 | H12: A-MC6 | I12: A-MC7 | J12: A-MC8 | K12: A-MC9 | L12: A-MC10 | M12: A-MC11 | N12: A-MC12 | O12: A-MC13 | P12: A-MC14 | Q12: A-MC15 | R12: A-MC16 | S12: A-MC17 | T12: A-NR1 | U12: A-NR2 | V12: A-NR3 | W12: B-MC1 | X12: B-MC2 | Y12: B-MC3 | Z12: B-MC4 | AA12: B-MC5 | AB12: B-MC6 | AC12: B-MC7 | AD12: B-MC8 | AE12: B-MC9 | AF12: B-NR1 | AG12: B-NR2 | AH12: B-NR3 | AI12: B-WR1 | AJ12: B-WR2 | AK12: B-WR3 | AL12: B-WR4
A13: Maximum points (input) | C13: 1 | D13: 1 | E13: 1 | F13: 1 | G13: 1 | H13: 1 | I13: 1 | J13: 1 | K13: 1 | L13: 1 | M13: 1 | N13: 1 | O13: 1 | P13: 1 | Q13: 1 | R13: 1 | S13: 1 | T13: 2 | U13: 2 | V13: 2 | W13: 1 | X13: 1 | Y13: 1 | Z13: 1 | AA13: 1 | AB13: 1 | AC13: 1 | AD13: 1 | AE13: 1 | AF13: 3 | AG13: 2 | AH13: 3 | AI13: 1 | AJ13: 3 | AK13: 2 | AL13: 2
A14: Response type | C14: MC | D14: MC | E14: MC | F14: MC | G14: MC | H14: MC | I14: MC | J14: MC | K14: MC | L14: MC | M14: MC | N14: MC | O14: MC | P14: MC | Q14: MC | R14: MC | S14: MC | T14: NR | U14: NR | V14: NR | W14: MC | X14: MC | Y14: MC | Z14: MC | AA14: MC | AB14: MC | AC14: MC | AD14: MC | AE14: MC | AF14: NR | AG14: NR | AH14: NR | AI14: WR | AJ14: WR | AK14: WR | AL14: WR
A15: Scored students | C15: =IF(OR(NOT(ISNUMBER(C$13)),C$13<=0,C$24>0),"",COUNTIFS(C$30:C$79,">=0",C$30:C$79,"<="&C$13,C$30:C$79,"<>",$A$30:$A$79,"<>")) -> 19 | D15: =IF(OR(NOT(ISNUMBER(D$13)),D$13<=0,D$24>0),"",COUNTIFS(D$30:D$79,">=0",D$30:D$79,"<="&D$13,D$30:D$79,"<>",$A$30:$A$79,"<>")) -> 19 | E15: =IF(OR(NOT(ISNUMBER(E$13)),E$13<=0,E$24>0),"",COUNTIFS(E$30:E$79,">=0",E$30:E$79,"<="&E$13,E$30:E$79,"<>",$A$30:$A$79,"<>")) -> 19 | F15: =IF(OR(NOT(ISNUMBER(F$13)),F$13<=0,F$24>0),"",COUNTIFS(F$30:F$79,">=0",F$30:F$79,"<="&F$13,F$30:F$79,"<>",$A$30:$A$79,"<>")) -> 19 | G15: =IF(OR(NOT(ISNUMBER(G$13)),G$13<=0,G$24>0),"",COUNTIFS(G$30:G$79,">=0",G$30:G$79,"<="&G$13,G$30:G$79,"<>",$A$30:$A$79,"<>")) -> 19 | H15: =IF(OR(NOT(ISNUMBER(H$13)),H$13<=0,H$24>0),"",COUNTIFS(H$30:H$79,">=0",H$30:H$79,"<="&H$13,H$30:H$79,"<>",$A$30:$A$79,"<>")) -> 19 | I15: =IF(OR(NOT(ISNUMBER(I$13)),I$13<=0,I$24>0),"",COUNTIFS(I$30:I$79,">=0",I$30:I$79,"<="&I$13,I$30:I$79,"<>",$A$30:$A$79,"<>")) -> 19 | J15: =IF(OR(NOT(ISNUMBER(J$13)),J$13<=0,J$24>0),"",COUNTIFS(J$30:J$79,">=0",J$30:J$79,"<="&J$13,J$30:J$79,"<>",$A$30:$A$79,"<>")) -> 19 | ... AL15: =IF(OR(NOT(ISNUMBER(AL$13)),AL$13<=0,AL$24>0),"",COUNTIFS(AL$30:AL$79,">=0",AL$30:AL$79,"<="&AL$13,AL$30:AL$79,"<>",$A$30:$A$79,"<>")) -> 19
A16: Mean points | C16: =IF(OR(OR(NOT(ISNUMBER(C$13)),C$13<=0,C$24>0),C$15=0),"",AVERAGEIFS(C$30:C$79,$A$30:$A$79,"<>",C$30:C$79,">=0",C$30:C$79,"<="&C$13)) -> 0.78947368 | D16: =IF(OR(OR(NOT(ISNUMBER(D$13)),D$13<=0,D$24>0),D$15=0),"",AVERAGEIFS(D$30:D$79,$A$30:$A$79,"<>",D$30:D$79,">=0",D$30:D$79,"<="&D$13)) -> 0.52631579 | E16: =IF(OR(OR(NOT(ISNUMBER(E$13)),E$13<=0,E$24>0),E$15=0),"",AVERAGEIFS(E$30:E$79,$A$30:$A$79,"<>",E$30:E$79,">=0",E$30:E$79,"<="&E$13)) -> 0.73684211 | F16: =IF(OR(OR(NOT(ISNUMBER(F$13)),F$13<=0,F$24>0),F$15=0),"",AVERAGEIFS(F$30:F$79,$A$30:$A$79,"<>",F$30:F$79,">=0",F$30:F$79,"<="&F$13)) -> 0.73684211 | G16: =IF(OR(OR(NOT(ISNUMBER(G$13)),G$13<=0,G$24>0),G$15=0),"",AVERAGEIFS(G$30:G$79,$A$30:$A$79,"<>",G$30:G$79,">=0",G$30:G$79,"<="&G$13)) -> 0.63157895 | H16: =IF(OR(OR(NOT(ISNUMBER(H$13)),H$13<=0,H$24>0),H$15=0),"",AVERAGEIFS(H$30:H$79,$A$30:$A$79,"<>",H$30:H$79,">=0",H$30:H$79,"<="&H$13)) -> 0.73684211 | I16: =IF(OR(OR(NOT(ISNUMBER(I$13)),I$13<=0,I$24>0),I$15=0),"",AVERAGEIFS(I$30:I$79,$A$30:$A$79,"<>",I$30:I$79,">=0",I$30:I$79,"<="&I$13)) -> 0.42105263 | J16: =IF(OR(OR(NOT(ISNUMBER(J$13)),J$13<=0,J$24>0),J$15=0),"",AVERAGEIFS(J$30:J$79,$A$30:$A$79,"<>",J$30:J$79,">=0",J$30:J$79,"<="&J$13)) -> 0.52631579 | ... AL16: =IF(OR(OR(NOT(ISNUMBER(AL$13)),AL$13<=0,AL$24>0),AL$15=0),"",AVERAGEIFS(AL$30:AL$79,$A$30:$A$79,"<>",AL$30:AL$79,">=0",AL$30:AL$79,"<="&AL$13)) -> 1.8421053
A17: Facility (mean / max) - Percent Correct | C17: =IF(OR(OR(NOT(ISNUMBER(C$13)),C$13<=0,C$24>0),C$15=0),"",C16/C$13) -> 0.78947368 | D17: =IF(OR(OR(NOT(ISNUMBER(D$13)),D$13<=0,D$24>0),D$15=0),"",D16/D$13) -> 0.52631579 | E17: =IF(OR(OR(NOT(ISNUMBER(E$13)),E$13<=0,E$24>0),E$15=0),"",E16/E$13) -> 0.73684211 | F17: =IF(OR(OR(NOT(ISNUMBER(F$13)),F$13<=0,F$24>0),F$15=0),"",F16/F$13) -> 0.73684211 | G17: =IF(OR(OR(NOT(ISNUMBER(G$13)),G$13<=0,G$24>0),G$15=0),"",G16/G$13) -> 0.63157895 | H17: =IF(OR(OR(NOT(ISNUMBER(H$13)),H$13<=0,H$24>0),H$15=0),"",H16/H$13) -> 0.73684211 | I17: =IF(OR(OR(NOT(ISNUMBER(I$13)),I$13<=0,I$24>0),I$15=0),"",I16/I$13) -> 0.42105263 | J17: =IF(OR(OR(NOT(ISNUMBER(J$13)),J$13<=0,J$24>0),J$15=0),"",J16/J$13) -> 0.52631579 | ... AL17: =IF(OR(OR(NOT(ISNUMBER(AL$13)),AL$13<=0,AL$24>0),AL$15=0),"",AL16/AL$13) -> 0.92105263
A18: Full-credit count | C18: =IF(OR(NOT(ISNUMBER(C$13)),C$13<=0,C$24>0),"",COUNTIFS(C$30:C$79,C$13,$A$30:$A$79,"<>")) -> 15 | D18: =IF(OR(NOT(ISNUMBER(D$13)),D$13<=0,D$24>0),"",COUNTIFS(D$30:D$79,D$13,$A$30:$A$79,"<>")) -> 10 | E18: =IF(OR(NOT(ISNUMBER(E$13)),E$13<=0,E$24>0),"",COUNTIFS(E$30:E$79,E$13,$A$30:$A$79,"<>")) -> 14 | F18: =IF(OR(NOT(ISNUMBER(F$13)),F$13<=0,F$24>0),"",COUNTIFS(F$30:F$79,F$13,$A$30:$A$79,"<>")) -> 14 | G18: =IF(OR(NOT(ISNUMBER(G$13)),G$13<=0,G$24>0),"",COUNTIFS(G$30:G$79,G$13,$A$30:$A$79,"<>")) -> 12 | H18: =IF(OR(NOT(ISNUMBER(H$13)),H$13<=0,H$24>0),"",COUNTIFS(H$30:H$79,H$13,$A$30:$A$79,"<>")) -> 14 | I18: =IF(OR(NOT(ISNUMBER(I$13)),I$13<=0,I$24>0),"",COUNTIFS(I$30:I$79,I$13,$A$30:$A$79,"<>")) -> 8 | J18: =IF(OR(NOT(ISNUMBER(J$13)),J$13<=0,J$24>0),"",COUNTIFS(J$30:J$79,J$13,$A$30:$A$79,"<>")) -> 10 | ... AL18: =IF(OR(NOT(ISNUMBER(AL$13)),AL$13<=0,AL$24>0),"",COUNTIFS(AL$30:AL$79,AL$13,$A$30:$A$79,"<>")) -> 17
A19: Partial-credit count | C19: =IF(OR(NOT(ISNUMBER(C$13)),C$13<=0,C$24>0),"",COUNTIFS(C$30:C$79,">0",C$30:C$79,"<"&C$13,$A$30:$A$79,"<>")) -> 0 | D19: =IF(OR(NOT(ISNUMBER(D$13)),D$13<=0,D$24>0),"",COUNTIFS(D$30:D$79,">0",D$30:D$79,"<"&D$13,$A$30:$A$79,"<>")) -> 0 | E19: =IF(OR(NOT(ISNUMBER(E$13)),E$13<=0,E$24>0),"",COUNTIFS(E$30:E$79,">0",E$30:E$79,"<"&E$13,$A$30:$A$79,"<>")) -> 0 | F19: =IF(OR(NOT(ISNUMBER(F$13)),F$13<=0,F$24>0),"",COUNTIFS(F$30:F$79,">0",F$30:F$79,"<"&F$13,$A$30:$A$79,"<>")) -> 0 | G19: =IF(OR(NOT(ISNUMBER(G$13)),G$13<=0,G$24>0),"",COUNTIFS(G$30:G$79,">0",G$30:G$79,"<"&G$13,$A$30:$A$79,"<>")) -> 0 | H19: =IF(OR(NOT(ISNUMBER(H$13)),H$13<=0,H$24>0),"",COUNTIFS(H$30:H$79,">0",H$30:H$79,"<"&H$13,$A$30:$A$79,"<>")) -> 0 | I19: =IF(OR(NOT(ISNUMBER(I$13)),I$13<=0,I$24>0),"",COUNTIFS(I$30:I$79,">0",I$30:I$79,"<"&I$13,$A$30:$A$79,"<>")) -> 0 | J19: =IF(OR(NOT(ISNUMBER(J$13)),J$13<=0,J$24>0),"",COUNTIFS(J$30:J$79,">0",J$30:J$79,"<"&J$13,$A$30:$A$79,"<>")) -> 0 | ... AL19: =IF(OR(NOT(ISNUMBER(AL$13)),AL$13<=0,AL$24>0),"",COUNTIFS(AL$30:AL$79,">0",AL$30:AL$79,"<"&AL$13,$A$30:$A$79,"<>")) -> 1
A20: Zero-credit count | C20: =IF(OR(NOT(ISNUMBER(C$13)),C$13<=0,C$24>0),"",COUNTIFS(C$30:C$79,0,C$30:C$79,"<>",$A$30:$A$79,"<>")) -> 4 | D20: =IF(OR(NOT(ISNUMBER(D$13)),D$13<=0,D$24>0),"",COUNTIFS(D$30:D$79,0,D$30:D$79,"<>",$A$30:$A$79,"<>")) -> 9 | E20: =IF(OR(NOT(ISNUMBER(E$13)),E$13<=0,E$24>0),"",COUNTIFS(E$30:E$79,0,E$30:E$79,"<>",$A$30:$A$79,"<>")) -> 5 | F20: =IF(OR(NOT(ISNUMBER(F$13)),F$13<=0,F$24>0),"",COUNTIFS(F$30:F$79,0,F$30:F$79,"<>",$A$30:$A$79,"<>")) -> 5 | G20: =IF(OR(NOT(ISNUMBER(G$13)),G$13<=0,G$24>0),"",COUNTIFS(G$30:G$79,0,G$30:G$79,"<>",$A$30:$A$79,"<>")) -> 7 | H20: =IF(OR(NOT(ISNUMBER(H$13)),H$13<=0,H$24>0),"",COUNTIFS(H$30:H$79,0,H$30:H$79,"<>",$A$30:$A$79,"<>")) -> 5 | I20: =IF(OR(NOT(ISNUMBER(I$13)),I$13<=0,I$24>0),"",COUNTIFS(I$30:I$79,0,I$30:I$79,"<>",$A$30:$A$79,"<>")) -> 11 | J20: =IF(OR(NOT(ISNUMBER(J$13)),J$13<=0,J$24>0),"",COUNTIFS(J$30:J$79,0,J$30:J$79,"<>",$A$30:$A$79,"<>")) -> 9 | ... AL20: =IF(OR(NOT(ISNUMBER(AL$13)),AL$13<=0,AL$24>0),"",COUNTIFS(AL$30:AL$79,0,AL$30:AL$79,"<>",$A$30:$A$79,"<>")) -> 1
A21: Ungraded students | C21: =IF(OR(NOT(ISNUMBER(C$13)),C$13<=0,C$24>0),"",COUNTIF($A$30:$A$79,"<>")-C$15) -> 1 | D21: =IF(OR(NOT(ISNUMBER(D$13)),D$13<=0,D$24>0),"",COUNTIF($A$30:$A$79,"<>")-D$15) -> 1 | E21: =IF(OR(NOT(ISNUMBER(E$13)),E$13<=0,E$24>0),"",COUNTIF($A$30:$A$79,"<>")-E$15) -> 1 | F21: =IF(OR(NOT(ISNUMBER(F$13)),F$13<=0,F$24>0),"",COUNTIF($A$30:$A$79,"<>")-F$15) -> 1 | G21: =IF(OR(NOT(ISNUMBER(G$13)),G$13<=0,G$24>0),"",COUNTIF($A$30:$A$79,"<>")-G$15) -> 1 | H21: =IF(OR(NOT(ISNUMBER(H$13)),H$13<=0,H$24>0),"",COUNTIF($A$30:$A$79,"<>")-H$15) -> 1 | I21: =IF(OR(NOT(ISNUMBER(I$13)),I$13<=0,I$24>0),"",COUNTIF($A$30:$A$79,"<>")-I$15) -> 1 | J21: =IF(OR(NOT(ISNUMBER(J$13)),J$13<=0,J$24>0),"",COUNTIF($A$30:$A$79,"<>")-J$15) -> 1 | ... AL21: =IF(OR(NOT(ISNUMBER(AL$13)),AL$13<=0,AL$24>0),"",COUNTIF($A$30:$A$79,"<>")-AL$15) -> 1
A22: Score SD (sample) | C22: =IF(OR(OR(NOT(ISNUMBER(C$13)),C$13<=0,C$24>0),C$15<2),"",_xlfn.STDEV.S(C$30:C$79)) -> 0.41885391 | D22: =IF(OR(OR(NOT(ISNUMBER(D$13)),D$13<=0,D$24>0),D$15<2),"",_xlfn.STDEV.S(D$30:D$79)) -> 0.51298918 | E22: =IF(OR(OR(NOT(ISNUMBER(E$13)),E$13<=0,E$24>0),E$15<2),"",_xlfn.STDEV.S(E$30:E$79)) -> 0.45241393 | F22: =IF(OR(OR(NOT(ISNUMBER(F$13)),F$13<=0,F$24>0),F$15<2),"",_xlfn.STDEV.S(F$30:F$79)) -> 0.45241393 | G22: =IF(OR(OR(NOT(ISNUMBER(G$13)),G$13<=0,G$24>0),G$15<2),"",_xlfn.STDEV.S(G$30:G$79)) -> 0.49559463 | H22: =IF(OR(OR(NOT(ISNUMBER(H$13)),H$13<=0,H$24>0),H$15<2),"",_xlfn.STDEV.S(H$30:H$79)) -> 0.45241393 | I22: =IF(OR(OR(NOT(ISNUMBER(I$13)),I$13<=0,I$24>0),I$15<2),"",_xlfn.STDEV.S(I$30:I$79)) -> 0.50725727 | J22: =IF(OR(OR(NOT(ISNUMBER(J$13)),J$13<=0,J$24>0),J$15<2),"",_xlfn.STDEV.S(J$30:J$79)) -> 0.51298918 | ... AL22: =IF(OR(OR(NOT(ISNUMBER(AL$13)),AL$13<=0,AL$24>0),AL$15<2),"",_xlfn.STDEV.S(AL$30:AL$79)) -> 0.50145986
A23: Item–rest correlation - Percent Upper Group Correct | C23: =IFERROR(__xludf.DUMMYFUNCTION("IF(OR(OR(NOT(ISNUMBER(C$13)),C$13<=0,C$24>0),COUNT($AM$30:$AM$79)<3),"""",IF(OR(STDEV.S(FILTER(C$30:C$79,ISNUMBER($AM$30:$AM$79)))=0,STDEV.S(FILTER($AM$30:$AM$79-C$30:C$79,ISNUMBER($AM$30:$AM$79)))=0),""n.a."",CORREL(FILTER(C$30:C$79,ISNUMBER($AM$30:$AM$7"&"9)),FILTER($AM$30:$AM$79-C$30:C$79,ISNUMBER($AM$30:$AM$79)))))"),0.39293897957146817) -> 0.39293898 | D23: =IFERROR(__xludf.DUMMYFUNCTION("IF(OR(OR(NOT(ISNUMBER(D$13)),D$13<=0,D$24>0),COUNT($AM$30:$AM$79)<3),"""",IF(OR(STDEV.S(FILTER(D$30:D$79,ISNUMBER($AM$30:$AM$79)))=0,STDEV.S(FILTER($AM$30:$AM$79-D$30:D$79,ISNUMBER($AM$30:$AM$79)))=0),""n.a."",CORREL(FILTER(D$30:D$79,ISNUMBER($AM$30:$AM$7"&"9)),FILTER($AM$30:$AM$79-D$30:D$79,ISNUMBER($AM$30:$AM$79)))))"),-0.01421395455357832) -> -0.014213955 | E23: =IFERROR(__xludf.DUMMYFUNCTION("IF(OR(OR(NOT(ISNUMBER(E$13)),E$13<=0,E$24>0),COUNT($AM$30:$AM$79)<3),"""",IF(OR(STDEV.S(FILTER(E$30:E$79,ISNUMBER($AM$30:$AM$79)))=0,STDEV.S(FILTER($AM$30:$AM$79-E$30:E$79,ISNUMBER($AM$30:$AM$79)))=0),""n.a."",CORREL(FILTER(E$30:E$79,ISNUMBER($AM$30:$AM$7"&"9)),FILTER($AM$30:$AM$79-E$30:E$79,ISNUMBER($AM$30:$AM$79)))))"),0.5940367649802991) -> 0.59403677 | F23: =IFERROR(__xludf.DUMMYFUNCTION("IF(OR(OR(NOT(ISNUMBER(F$13)),F$13<=0,F$24>0),COUNT($AM$30:$AM$79)<3),"""",IF(OR(STDEV.S(FILTER(F$30:F$79,ISNUMBER($AM$30:$AM$79)))=0,STDEV.S(FILTER($AM$30:$AM$79-F$30:F$79,ISNUMBER($AM$30:$AM$79)))=0),""n.a."",CORREL(FILTER(F$30:F$79,ISNUMBER($AM$30:$AM$7"&"9)),FILTER($AM$30:$AM$79-F$30:F$79,ISNUMBER($AM$30:$AM$79)))))"),0.36064110132963767) -> 0.3606411 | G23: =IFERROR(__xludf.DUMMYFUNCTION("IF(OR(OR(NOT(ISNUMBER(G$13)),G$13<=0,G$24>0),COUNT($AM$30:$AM$79)<3),"""",IF(OR(STDEV.S(FILTER(G$30:G$79,ISNUMBER($AM$30:$AM$79)))=0,STDEV.S(FILTER($AM$30:$AM$79-G$30:G$79,ISNUMBER($AM$30:$AM$79)))=0),""n.a."",CORREL(FILTER(G$30:G$79,ISNUMBER($AM$30:$AM$7"&"9)),FILTER($AM$30:$AM$79-G$30:G$79,ISNUMBER($AM$30:$AM$79)))))"),0.5911077515398248) -> 0.59110775 | H23: =IFERROR(__xludf.DUMMYFUNCTION("IF(OR(OR(NOT(ISNUMBER(H$13)),H$13<=0,H$24>0),COUNT($AM$30:$AM$79)<3),"""",IF(OR(STDEV.S(FILTER(H$30:H$79,ISNUMBER($AM$30:$AM$79)))=0,STDEV.S(FILTER($AM$30:$AM$79-H$30:H$79,ISNUMBER($AM$30:$AM$79)))=0),""n.a."",CORREL(FILTER(H$30:H$79,ISNUMBER($AM$30:$AM$7"&"9)),FILTER($AM$30:$AM$79-H$30:H$79,ISNUMBER($AM$30:$AM$79)))))"),0.31210740204500015) -> 0.3121074 | I23: =IFERROR(__xludf.DUMMYFUNCTION("IF(OR(OR(NOT(ISNUMBER(I$13)),I$13<=0,I$24>0),COUNT($AM$30:$AM$79)<3),"""",IF(OR(STDEV.S(FILTER(I$30:I$79,ISNUMBER($AM$30:$AM$79)))=0,STDEV.S(FILTER($AM$30:$AM$79-I$30:I$79,ISNUMBER($AM$30:$AM$79)))=0),""n.a."",CORREL(FILTER(I$30:I$79,ISNUMBER($AM$30:$AM$7"&"9)),FILTER($AM$30:$AM$79-I$30:I$79,ISNUMBER($AM$30:$AM$79)))))"),0.3285832458389668) -> 0.32858325 | J23: =IFERROR(__xludf.DUMMYFUNCTION("IF(OR(OR(NOT(ISNUMBER(J$13)),J$13<=0,J$24>0),COUNT($AM$30:$AM$79)<3),"""",IF(OR(STDEV.S(FILTER(J$30:J$79,ISNUMBER($AM$30:$AM$79)))=0,STDEV.S(FILTER($AM$30:$AM$79-J$30:J$79,ISNUMBER($AM$30:$AM$79)))=0),""n.a."",CORREL(FILTER(J$30:J$79,ISNUMBER($AM$30:$AM$7"&"9)),FILTER($AM$30:$AM$79-J$30:J$79,ISNUMBER($AM$30:$AM$79)))))"),0.5734292087942027) -> 0.57342921 | K23: =IFERROR(__xludf.DUMMYFUNCTION("IF(OR(OR(NOT(ISNUMBER(K$13)),K$13<=0,K$24>0),COUNT($AM$30:$AM$79)<3),"""",IF(OR(STDEV.S(FILTER(K$30:K$79,ISNUMBER($AM$30:$AM$79)))=0,STDEV.S(FILTER($AM$30:$AM$79-K$30:K$79,ISNUMBER($AM$30:$AM$79)))=0),""n.a."",CORREL(FILTER(K$30:K$79,ISNUMBER($AM$30:$AM$7"&"9)),FILTER($AM$30:$AM$79-K$30:K$79,ISNUMBER($AM$30:$AM$79)))))"),0.19608078323571967) -> 0.19608078 | L23: =IFERROR(__xludf.DUMMYFUNCTION("IF(OR(OR(NOT(ISNUMBER(L$13)),L$13<=0,L$24>0),COUNT($AM$30:$AM$79)<3),"""",IF(OR(STDEV.S(FILTER(L$30:L$79,ISNUMBER($AM$30:$AM$79)))=0,STDEV.S(FILTER($AM$30:$AM$79-L$30:L$79,ISNUMBER($AM$30:$AM$79)))=0),""n.a."",CORREL(FILTER(L$30:L$79,ISNUMBER($AM$30:$AM$7"&"9)),FILTER($AM$30:$AM$79-L$30:L$79,ISNUMBER($AM$30:$AM$79)))))"),0.5789319824864928) -> 0.57893198 | M23: =IFERROR(__xludf.DUMMYFUNCTION("IF(OR(OR(NOT(ISNUMBER(M$13)),M$13<=0,M$24>0),COUNT($AM$30:$AM$79)<3),"""",IF(OR(STDEV.S(FILTER(M$30:M$79,ISNUMBER($AM$30:$AM$79)))=0,STDEV.S(FILTER($AM$30:$AM$79-M$30:M$79,ISNUMBER($AM$30:$AM$79)))=0),""n.a."",CORREL(FILTER(M$30:M$79,ISNUMBER($AM$30:$AM$7"&"9)),FILTER($AM$30:$AM$79-M$30:M$79,ISNUMBER($AM$30:$AM$79)))))"),0.6651965800178761) -> 0.66519658 | N23: =IFERROR(__xludf.DUMMYFUNCTION("IF(OR(OR(NOT(ISNUMBER(N$13)),N$13<=0,N$24>0),COUNT($AM$30:$AM$79)<3),"""",IF(OR(STDEV.S(FILTER(N$30:N$79,ISNUMBER($AM$30:$AM$79)))=0,STDEV.S(FILTER($AM$30:$AM$79-N$30:N$79,ISNUMBER($AM$30:$AM$79)))=0),""n.a."",CORREL(FILTER(N$30:N$79,ISNUMBER($AM$30:$AM$7"&"9)),FILTER($AM$30:$AM$79-N$30:N$79,ISNUMBER($AM$30:$AM$79)))))"),0.24953680858241412) -> 0.24953681 | O23: =IFERROR(__xludf.DUMMYFUNCTION("IF(OR(OR(NOT(ISNUMBER(O$13)),O$13<=0,O$24>0),COUNT($AM$30:$AM$79)<3),"""",IF(OR(STDEV.S(FILTER(O$30:O$79,ISNUMBER($AM$30:$AM$79)))=0,STDEV.S(FILTER($AM$30:$AM$79-O$30:O$79,ISNUMBER($AM$30:$AM$79)))=0),""n.a."",CORREL(FILTER(O$30:O$79,ISNUMBER($AM$30:$AM$7"&"9)),FILTER($AM$30:$AM$79-O$30:O$79,ISNUMBER($AM$30:$AM$79)))))"),0.3938613776889741) -> 0.39386138 | P23: =IFERROR(__xludf.DUMMYFUNCTION("IF(OR(OR(NOT(ISNUMBER(P$13)),P$13<=0,P$24>0),COUNT($AM$30:$AM$79)<3),"""",IF(OR(STDEV.S(FILTER(P$30:P$79,ISNUMBER($AM$30:$AM$79)))=0,STDEV.S(FILTER($AM$30:$AM$79-P$30:P$79,ISNUMBER($AM$30:$AM$79)))=0),""n.a."",CORREL(FILTER(P$30:P$79,ISNUMBER($AM$30:$AM$7"&"9)),FILTER($AM$30:$AM$79-P$30:P$79,ISNUMBER($AM$30:$AM$79)))))"),0.3339713558833326) -> 0.33397136 | Q23: =IFERROR(__xludf.DUMMYFUNCTION("IF(OR(OR(NOT(ISNUMBER(Q$13)),Q$13<=0,Q$24>0),COUNT($AM$30:$AM$79)<3),"""",IF(OR(STDEV.S(FILTER(Q$30:Q$79,ISNUMBER($AM$30:$AM$79)))=0,STDEV.S(FILTER($AM$30:$AM$79-Q$30:Q$79,ISNUMBER($AM$30:$AM$79)))=0),""n.a."",CORREL(FILTER(Q$30:Q$79,ISNUMBER($AM$30:$AM$7"&"9)),FILTER($AM$30:$AM$79-Q$30:Q$79,ISNUMBER($AM$30:$AM$79)))))"),0.4887937206158562) -> 0.48879372 | R23: =IFERROR(__xludf.DUMMYFUNCTION("IF(OR(OR(NOT(ISNUMBER(R$13)),R$13<=0,R$24>0),COUNT($AM$30:$AM$79)<3),"""",IF(OR(STDEV.S(FILTER(R$30:R$79,ISNUMBER($AM$30:$AM$79)))=0,STDEV.S(FILTER($AM$30:$AM$79-R$30:R$79,ISNUMBER($AM$30:$AM$79)))=0),""n.a."",CORREL(FILTER(R$30:R$79,ISNUMBER($AM$30:$AM$7"&"9)),FILTER($AM$30:$AM$79-R$30:R$79,ISNUMBER($AM$30:$AM$79)))))"),0.2466225939543092) -> 0.24662259 | S23: =IFERROR(__xludf.DUMMYFUNCTION("IF(OR(OR(NOT(ISNUMBER(S$13)),S$13<=0,S$24>0),COUNT($AM$30:$AM$79)<3),"""",IF(OR(STDEV.S(FILTER(S$30:S$79,ISNUMBER($AM$30:$AM$79)))=0,STDEV.S(FILTER($AM$30:$AM$79-S$30:S$79,ISNUMBER($AM$30:$AM$79)))=0),""n.a."",CORREL(FILTER(S$30:S$79,ISNUMBER($AM$30:$AM$7"&"9)),FILTER($AM$30:$AM$79-S$30:S$79,ISNUMBER($AM$30:$AM$79)))))"),0.40608121933306646) -> 0.40608122 | T23: =IFERROR(__xludf.DUMMYFUNCTION("IF(OR(OR(NOT(ISNUMBER(T$13)),T$13<=0,T$24>0),COUNT($AM$30:$AM$79)<3),"""",IF(OR(STDEV.S(FILTER(T$30:T$79,ISNUMBER($AM$30:$AM$79)))=0,STDEV.S(FILTER($AM$30:$AM$79-T$30:T$79,ISNUMBER($AM$30:$AM$79)))=0),""n.a."",CORREL(FILTER(T$30:T$79,ISNUMBER($AM$30:$AM$7"&"9)),FILTER($AM$30:$AM$79-T$30:T$79,ISNUMBER($AM$30:$AM$79)))))"),0.7572210912437924) -> 0.75722109 | U23: =IFERROR(__xludf.DUMMYFUNCTION("IF(OR(OR(NOT(ISNUMBER(U$13)),U$13<=0,U$24>0),COUNT($AM$30:$AM$79)<3),"""",IF(OR(STDEV.S(FILTER(U$30:U$79,ISNUMBER($AM$30:$AM$79)))=0,STDEV.S(FILTER($AM$30:$AM$79-U$30:U$79,ISNUMBER($AM$30:$AM$79)))=0),""n.a."",CORREL(FILTER(U$30:U$79,ISNUMBER($AM$30:$AM$7"&"9)),FILTER($AM$30:$AM$79-U$30:U$79,ISNUMBER($AM$30:$AM$79)))))"),0.4473303738395715) -> 0.44733037 | V23: =IFERROR(__xludf.DUMMYFUNCTION("IF(OR(OR(NOT(ISNUMBER(V$13)),V$13<=0,V$24>0),COUNT($AM$30:$AM$79)<3),"""",IF(OR(STDEV.S(FILTER(V$30:V$79,ISNUMBER($AM$30:$AM$79)))=0,STDEV.S(FILTER($AM$30:$AM$79-V$30:V$79,ISNUMBER($AM$30:$AM$79)))=0),""n.a."",CORREL(FILTER(V$30:V$79,ISNUMBER($AM$30:$AM$7"&"9)),FILTER($AM$30:$AM$79-V$30:V$79,ISNUMBER($AM$30:$AM$79)))))"),0.3381990857406597) -> 0.33819909 | W23: =IFERROR(__xludf.DUMMYFUNCTION("IF(OR(OR(NOT(ISNUMBER(W$13)),W$13<=0,W$24>0),COUNT($AM$30:$AM$79)<3),"""",IF(OR(STDEV.S(FILTER(W$30:W$79,ISNUMBER($AM$30:$AM$79)))=0,STDEV.S(FILTER($AM$30:$AM$79-W$30:W$79,ISNUMBER($AM$30:$AM$79)))=0),""n.a."",CORREL(FILTER(W$30:W$79,ISNUMBER($AM$30:$AM$7"&"9)),FILTER($AM$30:$AM$79-W$30:W$79,ISNUMBER($AM$30:$AM$79)))))"),0.6240202912361323) -> 0.62402029 | X23: =IFERROR(__xludf.DUMMYFUNCTION("IF(OR(OR(NOT(ISNUMBER(X$13)),X$13<=0,X$24>0),COUNT($AM$30:$AM$79)<3),"""",IF(OR(STDEV.S(FILTER(X$30:X$79,ISNUMBER($AM$30:$AM$79)))=0,STDEV.S(FILTER($AM$30:$AM$79-X$30:X$79,ISNUMBER($AM$30:$AM$79)))=0),""n.a."",CORREL(FILTER(X$30:X$79,ISNUMBER($AM$30:$AM$7"&"9)),FILTER($AM$30:$AM$79-X$30:X$79,ISNUMBER($AM$30:$AM$79)))))"),0.46148770945925055) -> 0.46148771 | Y23: =IFERROR(__xludf.DUMMYFUNCTION("IF(OR(OR(NOT(ISNUMBER(Y$13)),Y$13<=0,Y$24>0),COUNT($AM$30:$AM$79)<3),"""",IF(OR(STDEV.S(FILTER(Y$30:Y$79,ISNUMBER($AM$30:$AM$79)))=0,STDEV.S(FILTER($AM$30:$AM$79-Y$30:Y$79,ISNUMBER($AM$30:$AM$79)))=0),""n.a."",CORREL(FILTER(Y$30:Y$79,ISNUMBER($AM$30:$AM$7"&"9)),FILTER($AM$30:$AM$79-Y$30:Y$79,ISNUMBER($AM$30:$AM$79)))))"),0.6804749848499504) -> 0.68047498 | Z23: =IFERROR(__xludf.DUMMYFUNCTION("IF(OR(OR(NOT(ISNUMBER(Z$13)),Z$13<=0,Z$24>0),COUNT($AM$30:$AM$79)<3),"""",IF(OR(STDEV.S(FILTER(Z$30:Z$79,ISNUMBER($AM$30:$AM$79)))=0,STDEV.S(FILTER($AM$30:$AM$79-Z$30:Z$79,ISNUMBER($AM$30:$AM$79)))=0),""n.a."",CORREL(FILTER(Z$30:Z$79,ISNUMBER($AM$30:$AM$7"&"9)),FILTER($AM$30:$AM$79-Z$30:Z$79,ISNUMBER($AM$30:$AM$79)))))"),0.5424826549442276) -> 0.54248265 | AA23: =IFERROR(__xludf.DUMMYFUNCTION("IF(OR(OR(NOT(ISNUMBER(AA$13)),AA$13<=0,AA$24>0),COUNT($AM$30:$AM$79)<3),"""",IF(OR(STDEV.S(FILTER(AA$30:AA$79,ISNUMBER($AM$30:$AM$79)))=0,STDEV.S(FILTER($AM$30:$AM$79-AA$30:AA$79,ISNUMBER($AM$30:$AM$79)))=0),""n.a."",CORREL(FILTER(AA$30:AA$79,ISNUMBER($AM"&"$30:$AM$79)),FILTER($AM$30:$AM$79-AA$30:AA$79,ISNUMBER($AM$30:$AM$79)))))"),0.4530056440551784) -> 0.45300564 | AB23: =IFERROR(__xludf.DUMMYFUNCTION("IF(OR(OR(NOT(ISNUMBER(AB$13)),AB$13<=0,AB$24>0),COUNT($AM$30:$AM$79)<3),"""",IF(OR(STDEV.S(FILTER(AB$30:AB$79,ISNUMBER($AM$30:$AM$79)))=0,STDEV.S(FILTER($AM$30:$AM$79-AB$30:AB$79,ISNUMBER($AM$30:$AM$79)))=0),""n.a."",CORREL(FILTER(AB$30:AB$79,ISNUMBER($AM"&"$30:$AM$79)),FILTER($AM$30:$AM$79-AB$30:AB$79,ISNUMBER($AM$30:$AM$79)))))"),0.3078535696758201) -> 0.30785357 | AC23: =IFERROR(__xludf.DUMMYFUNCTION("IF(OR(OR(NOT(ISNUMBER(AC$13)),AC$13<=0,AC$24>0),COUNT($AM$30:$AM$79)<3),"""",IF(OR(STDEV.S(FILTER(AC$30:AC$79,ISNUMBER($AM$30:$AM$79)))=0,STDEV.S(FILTER($AM$30:$AM$79-AC$30:AC$79,ISNUMBER($AM$30:$AM$79)))=0),""n.a."",CORREL(FILTER(AC$30:AC$79,ISNUMBER($AM"&"$30:$AM$79)),FILTER($AM$30:$AM$79-AC$30:AC$79,ISNUMBER($AM$30:$AM$79)))))"),0.4667074973426375) -> 0.4667075 | AD23: =IFERROR(__xludf.DUMMYFUNCTION("IF(OR(OR(NOT(ISNUMBER(AD$13)),AD$13<=0,AD$24>0),COUNT($AM$30:$AM$79)<3),"""",IF(OR(STDEV.S(FILTER(AD$30:AD$79,ISNUMBER($AM$30:$AM$79)))=0,STDEV.S(FILTER($AM$30:$AM$79-AD$30:AD$79,ISNUMBER($AM$30:$AM$79)))=0),""n.a."",CORREL(FILTER(AD$30:AD$79,ISNUMBER($AM"&"$30:$AM$79)),FILTER($AM$30:$AM$79-AD$30:AD$79,ISNUMBER($AM$30:$AM$79)))))"),0.5997586837710368) -> 0.59975868 | AE23: =IFERROR(__xludf.DUMMYFUNCTION("IF(OR(OR(NOT(ISNUMBER(AE$13)),AE$13<=0,AE$24>0),COUNT($AM$30:$AM$79)<3),"""",IF(OR(STDEV.S(FILTER(AE$30:AE$79,ISNUMBER($AM$30:$AM$79)))=0,STDEV.S(FILTER($AM$30:$AM$79-AE$30:AE$79,ISNUMBER($AM$30:$AM$79)))=0),""n.a."",CORREL(FILTER(AE$30:AE$79,ISNUMBER($AM"&"$30:$AM$79)),FILTER($AM$30:$AM$79-AE$30:AE$79,ISNUMBER($AM$30:$AM$79)))))"),0.26225459893321584) -> 0.2622546 | AF23: =IFERROR(__xludf.DUMMYFUNCTION("IF(OR(OR(NOT(ISNUMBER(AF$13)),AF$13<=0,AF$24>0),COUNT($AM$30:$AM$79)<3),"""",IF(OR(STDEV.S(FILTER(AF$30:AF$79,ISNUMBER($AM$30:$AM$79)))=0,STDEV.S(FILTER($AM$30:$AM$79-AF$30:AF$79,ISNUMBER($AM$30:$AM$79)))=0),""n.a."",CORREL(FILTER(AF$30:AF$79,ISNUMBER($AM"&"$30:$AM$79)),FILTER($AM$30:$AM$79-AF$30:AF$79,ISNUMBER($AM$30:$AM$79)))))"),0.6009085200663025) -> 0.60090852 | AG23: =IFERROR(__xludf.DUMMYFUNCTION("IF(OR(OR(NOT(ISNUMBER(AG$13)),AG$13<=0,AG$24>0),COUNT($AM$30:$AM$79)<3),"""",IF(OR(STDEV.S(FILTER(AG$30:AG$79,ISNUMBER($AM$30:$AM$79)))=0,STDEV.S(FILTER($AM$30:$AM$79-AG$30:AG$79,ISNUMBER($AM$30:$AM$79)))=0),""n.a."",CORREL(FILTER(AG$30:AG$79,ISNUMBER($AM"&"$30:$AM$79)),FILTER($AM$30:$AM$79-AG$30:AG$79,ISNUMBER($AM$30:$AM$79)))))"),0.5988737671909965) -> 0.59887377 | AH23: =IFERROR(__xludf.DUMMYFUNCTION("IF(OR(OR(NOT(ISNUMBER(AH$13)),AH$13<=0,AH$24>0),COUNT($AM$30:$AM$79)<3),"""",IF(OR(STDEV.S(FILTER(AH$30:AH$79,ISNUMBER($AM$30:$AM$79)))=0,STDEV.S(FILTER($AM$30:$AM$79-AH$30:AH$79,ISNUMBER($AM$30:$AM$79)))=0),""n.a."",CORREL(FILTER(AH$30:AH$79,ISNUMBER($AM"&"$30:$AM$79)),FILTER($AM$30:$AM$79-AH$30:AH$79,ISNUMBER($AM$30:$AM$79)))))"),0.4427458244785114) -> 0.44274582 | AI23: =IFERROR(__xludf.DUMMYFUNCTION("IF(OR(OR(NOT(ISNUMBER(AI$13)),AI$13<=0,AI$24>0),COUNT($AM$30:$AM$79)<3),"""",IF(OR(STDEV.S(FILTER(AI$30:AI$79,ISNUMBER($AM$30:$AM$79)))=0,STDEV.S(FILTER($AM$30:$AM$79-AI$30:AI$79,ISNUMBER($AM$30:$AM$79)))=0),""n.a."",CORREL(FILTER(AI$30:AI$79,ISNUMBER($AM"&"$30:$AM$79)),FILTER($AM$30:$AM$79-AI$30:AI$79,ISNUMBER($AM$30:$AM$79)))))"),0.43785146408789) -> 0.43785146 | AJ23: =IFERROR(__xludf.DUMMYFUNCTION("IF(OR(OR(NOT(ISNUMBER(AJ$13)),AJ$13<=0,AJ$24>0),COUNT($AM$30:$AM$79)<3),"""",IF(OR(STDEV.S(FILTER(AJ$30:AJ$79,ISNUMBER($AM$30:$AM$79)))=0,STDEV.S(FILTER($AM$30:$AM$79-AJ$30:AJ$79,ISNUMBER($AM$30:$AM$79)))=0),""n.a."",CORREL(FILTER(AJ$30:AJ$79,ISNUMBER($AM"&"$30:$AM$79)),FILTER($AM$30:$AM$79-AJ$30:AJ$79,ISNUMBER($AM$30:$AM$79)))))"),0.611377083495277) -> 0.61137708 | AK23: =IFERROR(__xludf.DUMMYFUNCTION("IF(OR(OR(NOT(ISNUMBER(AK$13)),AK$13<=0,AK$24>0),COUNT($AM$30:$AM$79)<3),"""",IF(OR(STDEV.S(FILTER(AK$30:AK$79,ISNUMBER($AM$30:$AM$79)))=0,STDEV.S(FILTER($AM$30:$AM$79-AK$30:AK$79,ISNUMBER($AM$30:$AM$79)))=0),""n.a."",CORREL(FILTER(AK$30:AK$79,ISNUMBER($AM"&"$30:$AM$79)),FILTER($AM$30:$AM$79-AK$30:AK$79,ISNUMBER($AM$30:$AM$79)))))"),0.6822357291806026) -> 0.68223573 | AL23: =IFERROR(__xludf.DUMMYFUNCTION("IF(OR(OR(NOT(ISNUMBER(AL$13)),AL$13<=0,AL$24>0),COUNT($AM$30:$AM$79)<3),"""",IF(OR(STDEV.S(FILTER(AL$30:AL$79,ISNUMBER($AM$30:$AM$79)))=0,STDEV.S(FILTER($AM$30:$AM$79-AL$30:AL$79,ISNUMBER($AM$30:$AM$79)))=0),""n.a."",CORREL(FILTER(AL$30:AL$79,ISNUMBER($AM"&"$30:$AM$79)),FILTER($AM$30:$AM$79-AL$30:AL$79,ISNUMBER($AM$30:$AM$79)))))"),0.5880607802734278) -> 0.58806078
A24: Invalid entries | C24: =IF(OR(NOT(ISNUMBER(C$13)),C$13<=0),COUNTA(C$30:C$79),COUNTA(C$30:C$79)-COUNTIFS(C$30:C$79,">=0",C$30:C$79,"<="&C$13,C$30:C$79,"<>",$A$30:$A$79,"<>")) -> 0 | D24: =IF(OR(NOT(ISNUMBER(D$13)),D$13<=0),COUNTA(D$30:D$79),COUNTA(D$30:D$79)-COUNTIFS(D$30:D$79,">=0",D$30:D$79,"<="&D$13,D$30:D$79,"<>",$A$30:$A$79,"<>")) -> 0 | E24: =IF(OR(NOT(ISNUMBER(E$13)),E$13<=0),COUNTA(E$30:E$79),COUNTA(E$30:E$79)-COUNTIFS(E$30:E$79,">=0",E$30:E$79,"<="&E$13,E$30:E$79,"<>",$A$30:$A$79,"<>")) -> 0 | F24: =IF(OR(NOT(ISNUMBER(F$13)),F$13<=0),COUNTA(F$30:F$79),COUNTA(F$30:F$79)-COUNTIFS(F$30:F$79,">=0",F$30:F$79,"<="&F$13,F$30:F$79,"<>",$A$30:$A$79,"<>")) -> 0 | G24: =IF(OR(NOT(ISNUMBER(G$13)),G$13<=0),COUNTA(G$30:G$79),COUNTA(G$30:G$79)-COUNTIFS(G$30:G$79,">=0",G$30:G$79,"<="&G$13,G$30:G$79,"<>",$A$30:$A$79,"<>")) -> 0 | H24: =IF(OR(NOT(ISNUMBER(H$13)),H$13<=0),COUNTA(H$30:H$79),COUNTA(H$30:H$79)-COUNTIFS(H$30:H$79,">=0",H$30:H$79,"<="&H$13,H$30:H$79,"<>",$A$30:$A$79,"<>")) -> 0 | I24: =IF(OR(NOT(ISNUMBER(I$13)),I$13<=0),COUNTA(I$30:I$79),COUNTA(I$30:I$79)-COUNTIFS(I$30:I$79,">=0",I$30:I$79,"<="&I$13,I$30:I$79,"<>",$A$30:$A$79,"<>")) -> 0 | J24: =IF(OR(NOT(ISNUMBER(J$13)),J$13<=0),COUNTA(J$30:J$79),COUNTA(J$30:J$79)-COUNTIFS(J$30:J$79,">=0",J$30:J$79,"<="&J$13,J$30:J$79,"<>",$A$30:$A$79,"<>")) -> 0 | ... AL24: =IF(OR(NOT(ISNUMBER(AL$13)),AL$13<=0),COUNTA(AL$30:AL$79),COUNTA(AL$30:AL$79)-COUNTIFS(AL$30:AL$79,">=0",AL$30:AL$79,"<="&AL$13,AL$30:AL$79,"<>",$A$30:$A$79,"<>")) -> 0
A25: Status | C25: =IF(C24>0,"Check scores",IF(OR(NOT(ISNUMBER(C$13)),C$13<=0),"Set maximum",IF(C$15=0,"Enter scores","Ready"))) -> Ready | D25: =IF(D24>0,"Check scores",IF(OR(NOT(ISNUMBER(D$13)),D$13<=0),"Set maximum",IF(D$15=0,"Enter scores","Ready"))) -> Ready | E25: =IF(E24>0,"Check scores",IF(OR(NOT(ISNUMBER(E$13)),E$13<=0),"Set maximum",IF(E$15=0,"Enter scores","Ready"))) -> Ready | F25: =IF(F24>0,"Check scores",IF(OR(NOT(ISNUMBER(F$13)),F$13<=0),"Set maximum",IF(F$15=0,"Enter scores","Ready"))) -> Ready | G25: =IF(G24>0,"Check scores",IF(OR(NOT(ISNUMBER(G$13)),G$13<=0),"Set maximum",IF(G$15=0,"Enter scores","Ready"))) -> Ready | H25: =IF(H24>0,"Check scores",IF(OR(NOT(ISNUMBER(H$13)),H$13<=0),"Set maximum",IF(H$15=0,"Enter scores","Ready"))) -> Ready | I25: =IF(I24>0,"Check scores",IF(OR(NOT(ISNUMBER(I$13)),I$13<=0),"Set maximum",IF(I$15=0,"Enter scores","Ready"))) -> Ready | J25: =IF(J24>0,"Check scores",IF(OR(NOT(ISNUMBER(J$13)),J$13<=0),"Set maximum",IF(J$15=0,"Enter scores","Ready"))) -> Ready | ... AL25: =IF(AL24>0,"Check scores",IF(OR(NOT(ISNUMBER(AL$13)),AL$13<=0),"Set maximum",IF(AL$15=0,"Enter scores","Ready"))) -> Ready
A26: Conclusion | C26: Keep | D26: Remove | E26: Keep | F26: Keep | G26: Keep | H26: Keep | I26: Keep | J26: Keep | K26: Keep | L26: Keep | M26: Keep | N26: Keep | O26: Keep | P26: Keep | Q26: Keep | R26: Maybe | S26: Keep | T26: Keep | U26: Keep | V26: Maybe | W26: Keep | X26: Keep | Y26: Keep | Z26: Keep | AA26: Keep | AB26: Keep | AC26: Keep | AD26: Keep | AE26: Keep | AF26: Keep | AG26: Keep | AH26: Keep | AI26: Keep | AJ26: Keep | AK26: Keep | AL26: Keep
A28: Score entry (inputs)
A29: Student number | B29: Student name | C29: =C12 -> A-MC1 | D29: =D12 -> A-MC2 | E29: =E12 -> A-MC3 | F29: =F12 -> A-MC4 | G29: =G12 -> A-MC5 | H29: =H12 -> A-MC6 | I29: =I12 -> A-MC7 | J29: =J12 -> A-MC8 | ... AL29: =AL12 -> B-WR4 | AM29: Complete total | AN29: Percent | AO29: Invalid scores
A30: =IF(ExponentsPractic_pst!A9="","",ExponentsPractic_pst!A9) -> 26281 | B30: =IF(ExponentsPractic_pst!B9="","",ExponentsPractic_pst!B9) -> Annicchiarico, Cohen | C30: 1 | D30: 1 | E30: 1 | F30: 1 | G30: 1 | H30: 1 | I30: 1 | J30: 1 | K30: 0 | L30: 1 | M30: 1 | N30: 1 | O30: 1 | P30: 1 | Q30: 1 | R30: 0 | S30: 1 | T30: 2 | U30: 0 | V30: 0 | W30: 1 | X30: 1 | Y30: 0 | Z30: 0 | AA30: 1 | AB30: 1 | AC30: 1 | AD30: 1 | AE30: 1 | AF30: 0 | AG30: 2 | AH30: 0 | AI30: 1 | AJ30: 1 | AK30: 0 | AL30: 2 | AM30: =IF(OR($A30="",$B$9<>36,COUNT(C30:AL30)<>36,AO30>0),"",SUM(C30:AL30)) -> 30 | AN30: =IF(ISNUMBER(AM30),AM30/$D$9,"") -> 0.625 | AO30: =IF(AND($A30="",COUNTA(C30:AL30)=0),"",IF($A30="",COUNTA(C30:AL30),COUNTA(C30:AL30)-SUMPRODUCT(--ISNUMBER(C30:AL30),--ISNUMBER($C$13:$AL$13),--($C$13:$AL$13>0),--(C30:AL30>=0),--(C30:AL30<=$C$13:$AL$13)))) -> 0
A31: =IF(ExponentsPractic_pst!A10="","",ExponentsPractic_pst!A10) -> 26285 | B31: =IF(ExponentsPractic_pst!B10="","",ExponentsPractic_pst!B10) -> Butcher, AJ | C31: 0 | D31: 0 | E31: 0 | F31: 0 | G31: 0 | H31: 1 | I31: 1 | J31: 0 | K31: 0 | L31: 0 | M31: 1 | N31: 0 | O31: 1 | P31: 1 | Q31: 1 | R31: 0 | S31: 1 | T31: 2 | U31: 2 | V31: 0 | W31: 1 | X31: 1 | Y31: 1 | Z31: 0 | AA31: 1 | AB31: 1 | AC31: 1 | AD31: 1 | AE31: 1 | AF31: 2 | AG31: 2 | AH31: 1 | AI31: 0.5 | AJ31: 0 | AK31: 2 | AL31: 2 | AM31: =IF(OR($A31="",$B$9<>36,COUNT(C31:AL31)<>36,AO31>0),"",SUM(C31:AL31)) -> 28.5 | AN31: =IF(ISNUMBER(AM31),AM31/$D$9,"") -> 0.59375 | AO31: =IF(AND($A31="",COUNTA(C31:AL31)=0),"",IF($A31="",COUNTA(C31:AL31),COUNTA(C31:AL31)-SUMPRODUCT(--ISNUMBER(C31:AL31),--ISNUMBER($C$13:$AL$13),--($C$13:$AL$13>0),--(C31:AL31>=0),--(C31:AL31<=$C$13:$AL$13)))) -> 0
A32: =IF(ExponentsPractic_pst!A11="","",ExponentsPractic_pst!A11) -> 37905 | B32: =IF(ExponentsPractic_pst!B11="","",ExponentsPractic_pst!B11) -> Crann, Meekyo | C32: 0 | D32: 1 | E32: 0 | F32: 1 | G32: 0 | H32: 1 | I32: 0 | J32: 0 | K32: 0 | L32: 0 | M32: 0 | N32: 1 | O32: 0 | P32: 1 | Q32: 1 | R32: 0 | S32: 0 | T32: 0 | U32: 0 | V32: 0 | W32: 0 | X32: 0 | Y32: 0 | Z32: 0 | AA32: 1 | AB32: 0 | AC32: 1 | AD32: 0 | AE32: 0 | AF32: 1 | AG32: 0 | AH32: 2 | AI32: 0 | AJ32: 0 | AK32: 0 | AL32: 1 | AM32: =IF(OR($A32="",$B$9<>36,COUNT(C32:AL32)<>36,AO32>0),"",SUM(C32:AL32)) -> 12 | AN32: =IF(ISNUMBER(AM32),AM32/$D$9,"") -> 0.25 | AO32: =IF(AND($A32="",COUNTA(C32:AL32)=0),"",IF($A32="",COUNTA(C32:AL32),COUNTA(C32:AL32)-SUMPRODUCT(--ISNUMBER(C32:AL32),--ISNUMBER($C$13:$AL$13),--($C$13:$AL$13>0),--(C32:AL32>=0),--(C32:AL32<=$C$13:$AL$13)))) -> 0
A33: =IF(ExponentsPractic_pst!A12="","",ExponentsPractic_pst!A12) -> 28574 | B33: =IF(ExponentsPractic_pst!B12="","",ExponentsPractic_pst!B12) -> Dahl, Jake | C33: 0 | D33: 0 | E33: 0 | F33: 1 | G33: 0 | H33: 0 | I33: 0 | J33: 0 | K33: 0 | L33: 0 | M33: 1 | N33: 1 | O33: 1 | P33: 1 | Q33: 1 | R33: 0 | S33: 1 | T33: 0 | U33: 0 | V33: 0 | W33: 1 | X33: 0 | Y33: 0 | Z33: 0 | AA33: 1 | AB33: 1 | AC33: 1 | AD33: 1 | AE33: 1 | AF33: 1 | AG33: 2 | AH33: 3 | AI33: 1 | AJ33: 0 | AK33: 0 | AL33: 2 | AM33: =IF(OR($A33="",$B$9<>36,COUNT(C33:AL33)<>36,AO33>0),"",SUM(C33:AL33)) -> 22 | AN33: =IF(ISNUMBER(AM33),AM33/$D$9,"") -> 0.45833333 | AO33: =IF(AND($A33="",COUNTA(C33:AL33)=0),"",IF($A33="",COUNTA(C33:AL33),COUNTA(C33:AL33)-SUMPRODUCT(--ISNUMBER(C33:AL33),--ISNUMBER($C$13:$AL$13),--($C$13:$AL$13>0),--(C33:AL33>=0),--(C33:AL33<=$C$13:$AL$13)))) -> 0
A34: =IF(ExponentsPractic_pst!A13="","",ExponentsPractic_pst!A13) -> 26288 | B34: =IF(ExponentsPractic_pst!B13="","",ExponentsPractic_pst!B13) -> Dick, Calder | C34: 1 | D34: 1 | E34: 1 | F34: 1 | G34: 1 | H34: 1 | I34: 0 | J34: 1 | K34: 0 | L34: 1 | M34: 1 | N34: 0 | O34: 1 | P34: 1 | Q34: 1 | R34: 1 | S34: 1 | T34: 2 | U34: 0 | V34: 2 | W34: 1 | X34: 1 | Y34: 0 | Z34: 1 | AA34: 1 | AB34: 1 | AC34: 1 | AD34: 1 | AE34: 1 | AF34: 3 | AG34: 2 | AH34: 2 | AI34: 1 | AJ34: 1 | AK34: 2 | AL34: 2 | AM34: =IF(OR($A34="",$B$9<>36,COUNT(C34:AL34)<>36,AO34>0),"",SUM(C34:AL34)) -> 39 | AN34: =IF(ISNUMBER(AM34),AM34/$D$9,"") -> 0.8125 | AO34: =IF(AND($A34="",COUNTA(C34:AL34)=0),"",IF($A34="",COUNTA(C34:AL34),COUNTA(C34:AL34)-SUMPRODUCT(--ISNUMBER(C34:AL34),--ISNUMBER($C$13:$AL$13),--($C$13:$AL$13>0),--(C34:AL34>=0),--(C34:AL34<=$C$13:$AL$13)))) -> 0
A35: =IF(ExponentsPractic_pst!A14="","",ExponentsPractic_pst!A14) -> 26289 | B35: =IF(ExponentsPractic_pst!B14="","",ExponentsPractic_pst!B14) -> Ewanchuk, Brayden | C35: 1 | D35: 0 | E35: 1 | F35: 0 | G35: 1 | H35: 0 | I35: 0 | J35: 1 | K35: 0 | L35: 0 | M35: 1 | N35: 1 | O35: 1 | P35: 1 | Q35: 1 | R35: 0 | S35: 1 | T35: 2 | U35: 2 | V35: 0 | W35: 1 | X35: 0 | Y35: 0 | Z35: 0 | AA35: 1 | AB35: 0 | AC35: 1 | AD35: 1 | AE35: 1 | AF35: 2 | AG35: 2 | AH35: 2 | AI35: 0.5 | AJ35: 2.5 | AK35: 2 | AL35: 2 | AM35: =IF(OR($A35="",$B$9<>36,COUNT(C35:AL35)<>36,AO35>0),"",SUM(C35:AL35)) -> 32 | AN35: =IF(ISNUMBER(AM35),AM35/$D$9,"") -> 0.66666667 | AO35: =IF(AND($A35="",COUNTA(C35:AL35)=0),"",IF($A35="",COUNTA(C35:AL35),COUNTA(C35:AL35)-SUMPRODUCT(--ISNUMBER(C35:AL35),--ISNUMBER($C$13:$AL$13),--($C$13:$AL$13>0),--(C35:AL35>=0),--(C35:AL35<=$C$13:$AL$13)))) -> 0
A36: =IF(ExponentsPractic_pst!A15="","",ExponentsPractic_pst!A15) -> 36672 | B36: =IF(ExponentsPractic_pst!B15="","",ExponentsPractic_pst!B15) -> Fulkerth, Hunter | C36: 1 | D36: 0 | E36: 1 | F36: 1 | G36: 1 | H36: 0 | I36: 1 | J36: 0 | K36: 1 | L36: 1 | M36: 1 | N36: 1 | O36: 1 | P36: 1 | Q36: 1 | R36: 0 | S36: 1 | T36: 1 | U36: 1 | V36: 2 | W36: 1 | X36: 1 | Y36: 0 | Z36: 1 | AA36: 1 | AB36: 1 | AC36: 1 | AD36: 1 | AE36: 0 | AF36: 1 | AG36: 2 | AH36: 2 | AI36: 0.5 | AJ36: 0 | AK36: 1 | AL36: 2 | AM36: =IF(OR($A36="",$B$9<>36,COUNT(C36:AL36)<>36,AO36>0),"",SUM(C36:AL36)) -> 32.5 | AN36: =IF(ISNUMBER(AM36),AM36/$D$9,"") -> 0.67708333 | AO36: =IF(AND($A36="",COUNTA(C36:AL36)=0),"",IF($A36="",COUNTA(C36:AL36),COUNTA(C36:AL36)-SUMPRODUCT(--ISNUMBER(C36:AL36),--ISNUMBER($C$13:$AL$13),--($C$13:$AL$13>0),--(C36:AL36>=0),--(C36:AL36<=$C$13:$AL$13)))) -> 0
A37: =IF(ExponentsPractic_pst!A16="","",ExponentsPractic_pst!A16) -> 24820 | B37: =IF(ExponentsPractic_pst!B16="","",ExponentsPractic_pst!B16) -> Grimsdale, Charles | C37: 1 | D37: 1 | E37: 1 | F37: 1 | G37: 1 | H37: 1 | I37: 0 | J37: 0 | K37: 0 | L37: 0 | M37: 0 | N37: 0 | O37: 1 | P37: 1 | Q37: 0 | R37: 0 | S37: 0 | T37: 0 | U37: 0 | V37: 0 | W37: 1 | X37: 1 | Y37: 0 | Z37: 0 | AA37: 1 | AB37: 1 | AC37: 1 | AD37: 1 | AE37: 1 | AF37: 2 | AG37: 0 | AH37: 0 | AI37: 0.5 | AJ37: 3 | AK37: 0 | AL37: 2 | AM37: =IF(OR($A37="",$B$9<>36,COUNT(C37:AL37)<>36,AO37>0),"",SUM(C37:AL37)) -> 22.5 | AN37: =IF(ISNUMBER(AM37),AM37/$D$9,"") -> 0.46875 | AO37: =IF(AND($A37="",COUNTA(C37:AL37)=0),"",IF($A37="",COUNTA(C37:AL37),COUNTA(C37:AL37)-SUMPRODUCT(--ISNUMBER(C37:AL37),--ISNUMBER($C$13:$AL$13),--($C$13:$AL$13>0),--(C37:AL37>=0),--(C37:AL37<=$C$13:$AL$13)))) -> 0
A38: =IF(ExponentsPractic_pst!A17="","",ExponentsPractic_pst!A17) -> 30685 | B38: =IF(ExponentsPractic_pst!B17="","",ExponentsPractic_pst!B17) -> Gudge, Hudson | AM38: =IF(OR($A38="",$B$9<>36,COUNT(C38:AL38)<>36,AO38>0),"",SUM(C38:AL38)) | AN38: =IF(ISNUMBER(AM38),AM38/$D$9,"") | AO38: =IF(AND($A38="",COUNTA(C38:AL38)=0),"",IF($A38="",COUNTA(C38:AL38),COUNTA(C38:AL38)-SUMPRODUCT(--ISNUMBER(C38:AL38),--ISNUMBER($C$13:$AL$13),--($C$13:$AL$13>0),--(C38:AL38>=0),--(C38:AL38<=$C$13:$AL$13)))) -> 0
A39: =IF(ExponentsPractic_pst!A18="","",ExponentsPractic_pst!A18) -> 26293 | B39: =IF(ExponentsPractic_pst!B18="","",ExponentsPractic_pst!B18) -> Hrynyk, Hallie | C39: 1 | D39: 0 | E39: 1 | F39: 1 | G39: 0 | H39: 1 | I39: 1 | J39: 1 | K39: 0 | L39: 1 | M39: 1 | N39: 0 | O39: 1 | P39: 0 | Q39: 1 | R39: 0 | S39: 1 | T39: 2 | U39: 2 | V39: 0 | W39: 1 | X39: 1 | Y39: 1 | Z39: 0 | AA39: 1 | AB39: 1 | AC39: 1 | AD39: 1 | AE39: 1 | AF39: 2 | AG39: 2 | AH39: 2 | AI39: 0.5 | AJ39: 0 | AK39: 2 | AL39: 2 | AM39: =IF(OR($A39="",$B$9<>36,COUNT(C39:AL39)<>36,AO39>0),"",SUM(C39:AL39)) -> 33.5 | AN39: =IF(ISNUMBER(AM39),AM39/$D$9,"") -> 0.69791667 | AO39: =IF(AND($A39="",COUNTA(C39:AL39)=0),"",IF($A39="",COUNTA(C39:AL39),COUNTA(C39:AL39)-SUMPRODUCT(--ISNUMBER(C39:AL39),--ISNUMBER($C$13:$AL$13),--($C$13:$AL$13>0),--(C39:AL39>=0),--(C39:AL39<=$C$13:$AL$13)))) -> 0
A40: =IF(ExponentsPractic_pst!A19="","",ExponentsPractic_pst!A19) -> 26521 | B40: =IF(ExponentsPractic_pst!B19="","",ExponentsPractic_pst!B19) -> Hughes, Jace | C40: 1 | D40: 1 | E40: 1 | F40: 0 | G40: 0 | H40: 1 | I40: 0 | J40: 0 | K40: 0 | L40: 0 | M40: 0 | N40: 1 | O40: 1 | P40: 1 | Q40: 0 | R40: 0 | S40: 1 | T40: 0 | U40: 2 | V40: 0 | W40: 1 | X40: 0 | Y40: 0 | Z40: 0 | AA40: 1 | AB40: 1 | AC40: 0 | AD40: 1 | AE40: 1 | AF40: 2 | AG40: 2 | AH40: 0 | AI40: 0 | AJ40: 0 | AK40: 0 | AL40: 2 | AM40: =IF(OR($A40="",$B$9<>36,COUNT(C40:AL40)<>36,AO40>0),"",SUM(C40:AL40)) -> 21 | AN40: =IF(ISNUMBER(AM40),AM40/$D$9,"") -> 0.4375 | AO40: =IF(AND($A40="",COUNTA(C40:AL40)=0),"",IF($A40="",COUNTA(C40:AL40),COUNTA(C40:AL40)-SUMPRODUCT(--ISNUMBER(C40:AL40),--ISNUMBER($C$13:$AL$13),--($C$13:$AL$13>0),--(C40:AL40>=0),--(C40:AL40<=$C$13:$AL$13)))) -> 0
A41: =IF(ExponentsPractic_pst!A20="","",ExponentsPractic_pst!A20) -> 28059 | B41: =IF(ExponentsPractic_pst!B20="","",ExponentsPractic_pst!B20) -> Kimmel, Emmy | C41: 1 | D41: 0 | E41: 0 | F41: 0 | G41: 0 | H41: 1 | I41: 0 | J41: 0 | K41: 1 | L41: 0 | M41: 1 | N41: 0 | O41: 1 | P41: 0 | Q41: 1 | R41: 1 | S41: 1 | T41: 0 | U41: 1 | V41: 0 | W41: 1 | X41: 1 | Y41: 0 | Z41: 0 | AA41: 1 | AB41: 0 | AC41: 1 | AD41: 1 | AE41: 1 | AF41: 2 | AG41: 2 | AH41: 0 | AI41: 1 | AJ41: 0 | AK41: 2 | AL41: 2 | AM41: =IF(OR($A41="",$B$9<>36,COUNT(C41:AL41)<>36,AO41>0),"",SUM(C41:AL41)) -> 24 | AN41: =IF(ISNUMBER(AM41),AM41/$D$9,"") -> 0.5 | AO41: =IF(AND($A41="",COUNTA(C41:AL41)=0),"",IF($A41="",COUNTA(C41:AL41),COUNTA(C41:AL41)-SUMPRODUCT(--ISNUMBER(C41:AL41),--ISNUMBER($C$13:$AL$13),--($C$13:$AL$13>0),--(C41:AL41>=0),--(C41:AL41<=$C$13:$AL$13)))) -> 0
A42: =IF(ExponentsPractic_pst!A21="","",ExponentsPractic_pst!A21) -> 26657 | B42: =IF(ExponentsPractic_pst!B21="","",ExponentsPractic_pst!B21) -> Krueger, Colin | C42: 1 | D42: 1 | E42: 1 | F42: 1 | G42: 1 | H42: 1 | I42: 1 | J42: 0 | K42: 1 | L42: 0 | M42: 1 | N42: 0 | O42: 1 | P42: 1 | Q42: 1 | R42: 0 | S42: 1 | T42: 2 | U42: 0 | V42: 0 | W42: 1 | X42: 0 | Y42: 0 | Z42: 0 | AA42: 1 | AB42: 0 | AC42: 0 | AD42: 0 | AE42: 0 | AF42: 2 | AG42: 0 | AH42: 0 | AI42: 1 | AJ42: 0 | AK42: 2 | AL42: 2 | AM42: =IF(OR($A42="",$B$9<>36,COUNT(C42:AL42)<>36,AO42>0),"",SUM(C42:AL42)) -> 24 | AN42: =IF(ISNUMBER(AM42),AM42/$D$9,"") -> 0.5 | AO42: =IF(AND($A42="",COUNTA(C42:AL42)=0),"",IF($A42="",COUNTA(C42:AL42),COUNTA(C42:AL42)-SUMPRODUCT(--ISNUMBER(C42:AL42),--ISNUMBER($C$13:$AL$13),--($C$13:$AL$13>0),--(C42:AL42>=0),--(C42:AL42<=$C$13:$AL$13)))) -> 0
A43: =IF(ExponentsPractic_pst!A22="","",ExponentsPractic_pst!A22) -> 26297 | B43: =IF(ExponentsPractic_pst!B22="","",ExponentsPractic_pst!B22) -> Mueller, Marco | C43: 1 | D43: 1 | E43: 1 | F43: 1 | G43: 1 | H43: 1 | I43: 0 | J43: 1 | K43: 1 | L43: 1 | M43: 1 | N43: 1 | O43: 1 | P43: 1 | Q43: 1 | R43: 1 | S43: 1 | T43: 2 | U43: 1 | V43: 2 | W43: 1 | X43: 1 | Y43: 1 | Z43: 1 | AA43: 1 | AB43: 1 | AC43: 1 | AD43: 1 | AE43: 1 | AF43: 3 | AG43: 2 | AH43: 3 | AI43: 1 | AJ43: 3 | AK43: 2 | AL43: 2 | AM43: =IF(OR($A43="",$B$9<>36,COUNT(C43:AL43)<>36,AO43>0),"",SUM(C43:AL43)) -> 46 | AN43: =IF(ISNUMBER(AM43),AM43/$D$9,"") -> 0.95833333 | AO43: =IF(AND($A43="",COUNTA(C43:AL43)=0),"",IF($A43="",COUNTA(C43:AL43),COUNTA(C43:AL43)-SUMPRODUCT(--ISNUMBER(C43:AL43),--ISNUMBER($C$13:$AL$13),--($C$13:$AL$13>0),--(C43:AL43>=0),--(C43:AL43<=$C$13:$AL$13)))) -> 0
...
